Traceback (most recent call last):
  File "/Users/andrewchen/Library/Python/3.9/lib/python/site-packages/discord/ext/commands/core.py", line 200, in wrapped
    ret = await coro(*args, **kwargs)
  File "/Users/andrewchen/PycharmProjects/scibowlbot/commands/question2.py", line 72, in q
    raise err  # Raise error as discord.ext.commands error instead of normal console error that displays in shell
  File "/Users/andrewchen/PycharmProjects/scibowlbot/commands/question2.py", line 70, in q
    await obj.run()
  File "/Users/andrewchen/PycharmProjects/scibowlbot/commands/question2.py", line 192, in run
    self.question_header = "**" + self.question_json[
KeyError: 'category'

The above exception was the direct cause of the following exception:

Traceback (most recent call last):
  File "/Users/andrewchen/Library/Python/3.9/lib/python/site-packages/discord/ext/commands/bot.py", line 1330, in invoke
    await ctx.command.invoke(ctx)
  File "/Users/andrewchen/Library/Python/3.9/lib/python/site-packages/discord/ext/commands/core.py", line 995, in invoke
    await injected(*ctx.args, **ctx.kwargs)  # type: ignore
  File "/Users/andrewchen/Library/Python/3.9/lib/python/site-packages/discord/ext/commands/core.py", line 209, in wrapped
    raise CommandInvokeError(exc) from exc
discord.ext.commands.errors.CommandInvokeError: Command raised an exception: KeyError: 'category'
